Workbook

Sheet Deal Analyzer
A1: WHOLESALE DEAL ANALYZER v2 — Ohio (edit yellow cells)
A2: Monte Carlo sheet re-runs 1,000 trials every time you press F9 (Cmd+= on Mac).
A3: STEP 1 — INPUTS
A4: ARV (After-Repair Value) | B4: 160000 | C4: What it sells for fully renovated — pull comps
A5: Estimated rehab cost | B5: 40000 | C5: Contractor walk-through, before contingency
A6: Rehab contingency % | B6: 0.15 | C6: Buffer for overruns — applied below (v1 recommended it but never used it)
A7: Rule of thumb % (0.70 standard) | B7: 0.7 | C7: 0.70 tight markets, 0.65 slow ones
A8: Your target assignment fee | B8: 10000 | C8: Your profit — $5K–15K typical in OH
A9: Earnest money deposit (EMD) | B9: 500 | C9: YOUR cash at risk — $100–1,000 typical
A10: Marketing cost to find this deal | B10: 800 | C10: Mail / skip-trace / gas amortized per deal
A11: Buyer's selling + closing + holding costs | B11: 0.1 | C11: % of ARV: agent ~5–6%, closing ~2%, holding/financing ~2–3%
A12: Minimum buyer margin for a GO | B12: 0.2 | C12: Flippers want ~20%+ of ARV after ALL costs
A13: Chance the assignment closes | B13: 0.7 | C13: Your own close rate on contracted deals
A14: EMD lost if a deal falls through | B14: 0.5 | C14: 0% with a solid inspection/assignment contingency; 100% if you're in breach
A15: STEP 2 — MAXIMUM ALLOWABLE OFFER (MAO)
A16: Rehab incl. contingency | B16: =B5*(1+B6) | C16: What the buyer will actually spend
A17: ARV x rule % | B17: =B4*B7 | C17: The 70% ceiling on total investment
A18: Less: rehab incl. contingency | B18: =-B16
A19: Less: your assignment fee | B19: =-B8
A20: MAO — max you offer the seller | B20: =MAX(0,B17+B18+B19) | C20: Offer at or BELOW this. This is the whole game.
A22: STEP 3 — YOUR NUMBERS
A23: Actual price you contract with seller | B23: 60000 | C23: Aim at/below MAO in B20
A24: Price you assign to end buyer | B24: =B23+B8 | C24: Seller price + your fee
A25: Your gross profit (assignment fee) | B25: =B8
A26: Your net profit if it closes | B26: =B8-B10 | C26: Fee minus marketing
A27: Cash you put at risk | B27: =B9+B10 | C27: EMD + marketing (v1 counted EMD only)
A28: Return on cash at risk | B28: =IF(B27=0,0,B26/B27) | C28: Net profit / (EMD + marketing)
A29: Expected profit (weighted by close rate) | B29: =B13*B26-(1-B13)*(B10+B9*B14) | C29: Closes: net profit. Falls through: lose marketing + the EMD share in B14
A31: STEP 4 — DOES IT WORK FOR YOUR END BUYER?
A32: A cash buyer/flipper only says yes if THEY still profit after every cost.
A33: Buyer's all-in (assign + rehab + costs) | B33: =B24+B16+B4*B11 | C33: v1 omitted selling/closing/holding costs
A34: Buyer's projected profit | B34: =B4-B33 | C34: ARV minus their true all-in
A35: Buyer's margin vs ARV | B35: =IF(B4=0,0,B34/B4) | C35: Compared with the minimum in B12
A37: STEP 5 — GO / NO-GO SIGNAL
A38: Deal signal | B38: =IF(B23>B20,"NO-GO: offer above MAO",IF(B35<B12,"WEAK: buyer margin below "&TEXT(B12,"0%"),IF(B29<=0,"NO-GO: expected profit ≤ 0","GO"))) | C38: GO needs: offer ≤ MAO, buyer margin ≥ B12, expected profit > 0
A39: Monte Carlo: chance the deal works | B39: ='Monte Carlo'!F5 | C39: Share of 1,000 simulated outcomes where it closes at a profit
A41: OHIO MEDIAN PRICE REFERENCE (2026) — verify before relying on these
A42: Cleveland median | B42: ~$135,000
A43: Dayton median | B43: ~$130,000
A44: Columbus median | B44: ~$290,000
...

Sheet Monte Carlo
A1: MONTE CARLO — 1,000 live trials (press F9 to re-run)
A2: Each trial draws an ARV, a rehab overrun and whether the deal closes, then recomputes the buyer's margin and your profit.
A3: RESULTS | I3: ASSUMPTIONS (edit yellow)
A4: Trials | B4: =COUNT(B12:B1011) | I4: ARV uncertainty (std dev) | J4: 0.08 | K4: Comps are rarely tighter than ±8%
A5: Deal works (closes at a profit) | F5: =COUNTIF(G12:G1011,">0")/B4 | I5: Rehab overrun: mean | J5: 0.1 | K5: Average overrun on the base estimate, before contingency
A6: Buyer margin ≥ minimum | F6: =COUNTIF(F12:F1011,TRUE)/B4 | I6: Rehab overrun: std dev | J6: 0.15 | K6: Spread of overruns
A7: Average profit per deal | F7: =AVERAGE(G12:G1011) | I7: Other fall-through risk | J7: ='Deal Analyzer'!B13 | K7: From the analyzer's close rate
A8: Chance you lose money | F8: =COUNTIF(G12:G1011,"<0")/B4
A9: Buyer margin: 5th / median / 95th pct | D9: =PERCENTILE(E12:E1011,0.05) | E9: =MEDIAN(E12:E1011) | F9: =PERCENTILE(E12:E1011,0.95)
A11: Trial | B11: ARV draw | C11: Rehab draw | D11: Buyer all-in | E11: Buyer margin | F11: Buyer bites | G11: Your profit
A12: 1 | B12: =MAX(0,'Deal Analyzer'!$B$4*(1+NORM.INV(RAND(),0,$J$4))) | C12: ='Deal Analyzer'!$B$5*MAX(0.9,1+NORM.INV(RAND(),$J$5,$J$6)) | D12: ='Deal Analyzer'!$B$24+C12+B12*'Deal Analyzer'!$B$11 | E12: =IF(B12=0,0,(B12-D12)/B12) | F12: =E12>='Deal Analyzer'!$B$12 | G12: =IF(AND(F12,RAND()<$J$7),'Deal Analyzer'!$B$8-'Deal Analyzer'!$B$10,-('Deal Analyzer'!$B$10+'Deal Analyzer'!$B$9*'Deal Analyzer'!$B$14))
A13: 2 | B13: =MAX(0,'Deal Analyzer'!$B$4*(1+NORM.INV(RAND(),0,$J$4))) | C13: ='Deal Analyzer'!$B$5*MAX(0.9,1+NORM.INV(RAND(),$J$5,$J$6)) | D13: ='Deal Analyzer'!$B$24+C13+B13*'Deal Analyzer'!$B$11 | E13: =IF(B13=0,0,(B13-D13)/B13) | F13: =E13>='Deal Analyzer'!$B$12 | G13: =IF(AND(F13,RAND()<$J$7),'Deal Analyzer'!$B$8-'Deal Analyzer'!$B$10,-('Deal Analyzer'!$B$10+'Deal Analyzer'!$B$9*'Deal Analyzer'!$B$14))
A14: 3 | B14: =MAX(0,'Deal Analyzer'!$B$4*(1+NORM.INV(RAND(),0,$J$4))) | C14: ='Deal Analyzer'!$B$5*MAX(0.9,1+NORM.INV(RAND(),$J$5,$J$6)) | D14: ='Deal Analyzer'!$B$24+C14+B14*'Deal Analyzer'!$B$11 | E14: =IF(B14=0,0,(B14-D14)/B14) | F14: =E14>='Deal Analyzer'!$B$12 | G14: =IF(AND(F14,RAND()<$J$7),'Deal Analyzer'!$B$8-'Deal Analyzer'!$B$10,-('Deal Analyzer'!$B$10+'Deal Analyzer'!$B$9*'Deal Analyzer'!$B$14))
A15: 4 | B15: =MAX(0,'Deal Analyzer'!$B$4*(1+NORM.INV(RAND(),0,$J$4))) | C15: ='Deal Analyzer'!$B$5*MAX(0.9,1+NORM.INV(RAND(),$J$5,$J$6)) | D15: ='Deal Analyzer'!$B$24+C15+B15*'Deal Analyzer'!$B$11 | E15: =IF(B15=0,0,(B15-D15)/B15) | F15: =E15>='Deal Analyzer'!$B$12 | G15: =IF(AND(F15,RAND()<$J$7),'Deal Analyzer'!$B$8-'Deal Analyzer'!$B$10,-('Deal Analyzer'!$B$10+'Deal Analyzer'!$B$9*'Deal Analyzer'!$B$14))
A16: 5 | B16: =MAX(0,'Deal Analyzer'!$B$4*(1+NORM.INV(RAND(),0,$J$4))) | C16: ='Deal Analyzer'!$B$5*MAX(0.9,1+NORM.INV(RAND(),$J$5,$J$6)) | D16: ='Deal Analyzer'!$B$24+C16+B16*'Deal Analyzer'!$B$11 | E16: =IF(B16=0,0,(B16-D16)/B16) | F16: =E16>='Deal Analyzer'!$B$12 | G16: =IF(AND(F16,RAND()<$J$7),'Deal Analyzer'!$B$8-'Deal Analyzer'!$B$10,-('Deal Analyzer'!$B$10+'Deal Analyzer'!$B$9*'Deal Analyzer'!$B$14))
A17: 6 | B17: =MAX(0,'Deal Analyzer'!$B$4*(1+NORM.INV(RAND(),0,$J$4))) | C17: ='Deal Analyzer'!$B$5*MAX(0.9,1+NORM.INV(RAND(),$J$5,$J$6)) | D17: ='Deal Analyzer'!$B$24+C17+B17*'Deal Analyzer'!$B$11 | E17: =IF(B17=0,0,(B17-D17)/B17) | F17: =E17>='Deal Analyzer'!$B$12 | G17: =IF(AND(F17,RAND()<$J$7),'Deal Analyzer'!$B$8-'Deal Analyzer'!$B$10,-('Deal Analyzer'!$B$10+'Deal Analyzer'!$B$9*'Deal Analyzer'!$B$14))
A18: 7 | B18: =MAX(0,'Deal Analyzer'!$B$4*(1+NORM.INV(RAND(),0,$J$4))) | C18: ='Deal Analyzer'!$B$5*MAX(0.9,1+NORM.INV(RAND(),$J$5,$J$6)) | D18: ='Deal Analyzer'!$B$24+C18+B18*'Deal Analyzer'!$B$11 | E18: =IF(B18=0,0,(B18-D18)/B18) | F18: =E18>='Deal Analyzer'!$B$12 | G18: =IF(AND(F18,RAND()<$J$7),'Deal Analyzer'!$B$8-'Deal Analyzer'!$B$10,-('Deal Analyzer'!$B$10+'Deal Analyzer'!$B$9*'Deal Analyzer'!$B$14))
A19: 8 | B19: =MAX(0,'Deal Analyzer'!$B$4*(1+NORM.INV(RAND(),0,$J$4))) | C19: ='Deal Analyzer'!$B$5*MAX(0.9,1+NORM.INV(RAND(),$J$5,$J$6)) | D19: ='Deal Analyzer'!$B$24+C19+B19*'Deal Analyzer'!$B$11 | E19: =IF(B19=0,0,(B19-D19)/B19) | F19: =E19>='Deal Analyzer'!$B$12 | G19: =IF(AND(F19,RAND()<$J$7),'Deal Analyzer'!$B$8-'Deal Analyzer'!$B$10,-('Deal Analyzer'!$B$10+'Deal Analyzer'!$B$9*'Deal Analyzer'!$B$14))
A20: 9 | B20: =MAX(0,'Deal Analyzer'!$B$4*(1+NORM.INV(RAND(),0,$J$4))) | C20: ='Deal Analyzer'!$B$5*MAX(0.9,1+NORM.INV(RAND(),$J$5,$J$6)) | D20: ='Deal Analyzer'!$B$24+C20+B20*'Deal Analyzer'!$B$11 | E20: =IF(B20=0,0,(B20-D20)/B20) | F20: =E20>='Deal Analyzer'!$B$12 | G20: =IF(AND(F20,RAND()<$J$7),'Deal Analyzer'!$B$8-'Deal Analyzer'!$B$10,-('Deal Analyzer'!$B$10+'Deal Analyzer'!$B$9*'Deal Analyzer'!$B$14))
A21: 10 | B21: =MAX(0,'Deal Analyzer'!$B$4*(1+NORM.INV(RAND(),0,$J$4))) | C21: ='Deal Analyzer'!$B$5*MAX(0.9,1+NORM.INV(RAND(),$J$5,$J$6)) | D21: ='Deal Analyzer'!$B$24+C21+B21*'Deal Analyzer'!$B$11 | E21: =IF(B21=0,0,(B21-D21)/B21) | F21: =E21>='Deal Analyzer'!$B$12 | G21: =IF(AND(F21,RAND()<$J$7),'Deal Analyzer'!$B$8-'Deal Analyzer'!$B$10,-('Deal Analyzer'!$B$10+'Deal Analyzer'!$B$9*'Deal Analyzer'!$B$14))
A22: 11 | B22: =MAX(0,'Deal Analyzer'!$B$4*(1+NORM.INV(RAND(),0,$J$4))) | C22: ='Deal Analyzer'!$B$5*MAX(0.9,1+NORM.INV(RAND(),$J$5,$J$6)) | D22: ='Deal Analyzer'!$B$24+C22+B22*'Deal Analyzer'!$B$11 | E22: =IF(B22=0,0,(B22-D22)/B22) | F22: =E22>='Deal Analyzer'!$B$12 | G22: =IF(AND(F22,RAND()<$J$7),'Deal Analyzer'!$B$8-'Deal Analyzer'!$B$10,-('Deal Analyzer'!$B$10+'Deal Analyzer'!$B$9*'Deal Analyzer'!$B$14))
A23: 12 | B23: =MAX(0,'Deal Analyzer'!$B$4*(1+NORM.INV(RAND(),0,$J$4))) | C23: ='Deal Analyzer'!$B$5*MAX(0.9,1+NORM.INV(RAND(),$J$5,$J$6)) | D23: ='Deal Analyzer'!$B$24+C23+B23*'Deal Analyzer'!$B$11 | E23: =IF(B23=0,0,(B23-D23)/B23) | F23: =E23>='Deal Analyzer'!$B$12 | G23: =IF(AND(F23,RAND()<$J$7),'Deal Analyzer'!$B$8-'Deal Analyzer'!$B$10,-('Deal Analyzer'!$B$10+'Deal Analyzer'!$B$9*'Deal Analyzer'!$B$14))
... A1011: 1000 | B1011: =MAX(0,'Deal Analyzer'!$B$4*(1+NORM.INV(RAND(),0,$J$4))) | C1011: ='Deal Analyzer'!$B$5*MAX(0.9,1+NORM.INV(RAND(),$J$5,$J$6)) | D1011: ='Deal Analyzer'!$B$24+C1011+B1011*'Deal Analyzer'!$B$11 | E1011: =IF(B1011=0,0,(B1011-D1011)/B1011) | F1011: =E1011>='Deal Analyzer'!$B$12 | G1011: =IF(AND(F1011,RAND()<$J$7),'Deal Analyzer'!$B$8-'Deal Analyzer'!$B$10,-('Deal Analyzer'!$B$10+'Deal Analyzer'!$B$9*'Deal Analyzer'!$B$14))
